<?xml version="1.0"?>
<robot xmlns:xacro="http://www.ros.org/wiki/xacro" name="mon_robot">

  <!-- ================================================================ -->
  <!-- MACROS D'INERTIE -->
  <!-- ================================================================ -->
  
  <xacro:macro name="inertial_box" params="mass x y z *origin">
    <inertial>
      <xacro:insert_block name="origin"/>
      <mass value="${mass}" />
      <inertia ixx="${(1/12) * mass * (y*y+z*z)}" ixy="0.0" ixz="0.0"
               iyy="${(1/12) * mass * (x*x+z*z)}" iyz="0.0"
               izz="${(1/12) * mass * (x*x+y*y)}" />
    </inertial>
  </xacro:macro>

  <xacro:macro name="inertial_cylinder" params="mass length radius *origin">
    <inertial>
      <xacro:insert_block name="origin"/>
      <mass value="${mass}" />
      <inertia ixx="${(1/12) * mass * (3*radius*radius + length*length)}" ixy="0.0" ixz="0.0"
               iyy="${(1/12) * mass * (3*radius*radius + length*length)}" iyz="0.0"
               izz="${(1/2) * mass * (radius*radius)}" />
    </inertial>
  </xacro:macro>

  <!-- ================================================================ -->
  <!-- MATÉRIAUX -->
  <!-- ================================================================ -->
  
  <material name="blue"><color rgba="0 0 0.8 1"/></material>
  <material name="black"><color rgba="0 0 0 1"/></material>
  <material name="red"><color rgba="0.8 0 0 1"/></material>

  <!-- ================================================================ -->
  <!-- BASE_LINK (Point de référence) -->
  <!-- ================================================================ -->
  
  <link name="base_link"></link>

  <!-- ================================================================ -->
  <!-- CHASSIS -->
  <!-- ================================================================ -->
  
  <joint name="chassis_joint" type="fixed">
    <parent link="base_link"/>
    <child link="chassis"/>
    <origin xyz="-0.1 0 0"/>
  </joint>

  <link name="chassis">
    <visual>
      <origin xyz="0.1 0 0.025"/>
      <geometry><box size="0.3 0.3 0.05"/></geometry>
      <material name="blue"/>
    </visual>
    <collision>
      <origin xyz="0.1 0 0.025"/>
      <geometry><box size="0.3 0.3 0.05"/></geometry>
    </collision>
    <!-- 🔥 MASSE AUGMENTÉE: 0.5kg → 3.0kg -->
    <xacro:inertial_box mass="3.0" x="0.3" y="0.3" z="0.05">
        <origin xyz="0.1 0 0.025" rpy="0 0 0"/>
    </xacro:inertial_box>
  </link>

  <!-- ================================================================ -->
  <!-- LIDAR -->
  <!-- ================================================================ -->
  
  <link name="laser_frame">
    <visual>
      <origin xyz="0 0 0" rpy="0 0 0"/>
      <geometry>
        <cylinder radius="0.05" length="0.04"/>
      </geometry>
      <material name="red"/>
    </visual>
    <collision>
      <origin xyz="0 0 0" rpy="0 0 0"/>
      <geometry>
        <cylinder radius="0.05" length="0.04"/>
      </geometry>
    </collision>
    <!-- 🔥 MASSE AUGMENTÉE: 0.1kg → 0.5kg -->
    <xacro:inertial_cylinder mass="0.5" length="0.04" radius="0.05">
      <origin xyz="0 0 0" rpy="0 0 0"/>
    </xacro:inertial_cylinder>
  </link>

  <joint name="laser_joint" type="fixed">
    <parent link="chassis"/>
    <child link="laser_frame"/>
    <origin xyz="0.1 0 0.075" rpy="0 0 0"/>
  </joint>

  <!-- ================================================================ -->
  <!-- ROUES (4 roues motrices) -->
  <!-- ================================================================ -->
  
  <xacro:macro name="wheel" params="prefix x_reflect y_reflect">
    <link name="${prefix}_link">
      <visual>
        <geometry><cylinder radius="0.05" length="0.04"/></geometry>
        <material name="black"/>
      </visual>
      <collision>
        <geometry><cylinder radius="0.05" length="0.04"/></geometry>
      </collision>
      <!-- 🔥 MASSE AUGMENTÉE: 0.1kg → 0.3kg -->
      <xacro:inertial_cylinder mass="0.3" length="0.04" radius="0.05">
        <origin xyz="0 0 0" rpy="0 0 0"/>
      </xacro:inertial_cylinder>
    </link>

    <joint name="${prefix}_joint" type="continuous">
      <parent link="base_link"/>
      <child link="${prefix}_link"/>
      <origin xyz="${x_reflect*0.1} ${y_reflect*0.175} 0" rpy="-1.57 0 0"/>
      <axis xyz="0 0 1"/>
      <!-- 🔥 AJOUT DAMPING ET FRICTION DANS LE JOINT -->
      <dynamics damping="0.1" friction="0.1"/>
    </joint>
  </xacro:macro>

  <xacro:wheel prefix="front_left" x_reflect="1" y_reflect="1" />
  <xacro:wheel prefix="front_right" x_reflect="1" y_reflect="-1" />
  <xacro:wheel prefix="rear_left" x_reflect="-1" y_reflect="1" />
  <xacro:wheel prefix="rear_right" x_reflect="-1" y_reflect="-1" />

  <!-- ================================================================ -->
  <!-- ROS2_CONTROL -->
  <!-- ================================================================ -->
  
  <ros2_control name="GazeboSystem" type="system">
    <hardware>
      <plugin>gazebo_ros2_control/GazeboSystem</plugin>
    </hardware>
    
    <xacro:macro name="control_joint" params="name">
      <joint name="${name}">
        <command_interface name="velocity">
          <param name="min">-10</param>
          <param name="max">10</param>
        </command_interface>
        <state_interface name="position"/>
        <state_interface name="velocity"/>
      </joint>
    </xacro:macro>

    <xacro:control_joint name="front_left_joint"/>
    <xacro:control_joint name="front_right_joint"/>
    <xacro:control_joint name="rear_left_joint"/>
    <xacro:control_joint name="rear_right_joint"/>
  </ros2_control>

  <!-- ================================================================ -->
  <!-- GAZEBO - MATÉRIAUX ET PROPRIÉTÉS PHYSIQUES -->
  <!-- ================================================================ -->
  
  <!-- Chassis Gazebo -->
  <gazebo reference="chassis">
    <material>Gazebo/Blue</material>
    <!-- 🔥 AJOUT PROPRIÉTÉS PHYSIQUES -->
    <mu1>0.3</mu1>
    <mu2>0.3</mu2>
    <kp>1000000.0</kp>
    <kd>100.0</kd>
    <minDepth>0.001</minDepth>
    <maxVel>1.0</maxVel>
  </gazebo>
  
  <!-- LiDAR Gazebo -->
  <gazebo reference="laser_frame">
    <material>Gazebo/Red</material>
  </gazebo>
  
  <!-- 🔥 ROUES GAZEBO AVEC FRICTION MAXIMALE -->
  <gazebo reference="front_left_link">
    <material>Gazebo/Black</material>
    <!-- FRICTION ÉLEVÉE pour éviter glissement -->
    <mu1>1.5</mu1>
    <mu2>1.5</mu2>
    <!-- Raideur du contact -->
    <kp>1000000.0</kp>
    <kd>100.0</kd>
    <!-- Profondeur minimale de pénétration -->
    <minDepth>0.001</minDepth>
    <!-- Vitesse maximale de glissement -->
    <maxVel>0.1</maxVel>
    <!-- Surface properties -->
    <fdir1>1 0 0</fdir1>
  </gazebo>
  
  <gazebo reference="front_right_link">
    <material>Gazebo/Black</material>
    <mu1>1.5</mu1>
    <mu2>1.5</mu2>
    <kp>1000000.0</kp>
    <kd>100.0</kd>
    <minDepth>0.001</minDepth>
    <maxVel>0.1</maxVel>
    <fdir1>1 0 0</fdir1>
  </gazebo>
  
  <gazebo reference="rear_left_link">
    <material>Gazebo/Black</material>
    <mu1>1.5</mu1>
    <mu2>1.5</mu2>
    <kp>1000000.0</kp>
    <kd>100.0</kd>
    <minDepth>0.001</minDepth>
    <maxVel>0.1</maxVel>
    <fdir1>1 0 0</fdir1>
  </gazebo>
  
  <gazebo reference="rear_right_link">
    <material>Gazebo/Black</material>
    <mu1>1.5</mu1>
    <mu2>1.5</mu2>
    <kp>1000000.0</kp>
    <kd>100.0</kd>
    <minDepth>0.001</minDepth>
    <maxVel>0.1</maxVel>
    <fdir1>1 0 0</fdir1>
  </gazebo>

  <!-- ================================================================ -->
  <!-- PLUGIN LIDAR GAZEBO -->
  <!-- ================================================================ -->
  
  <gazebo reference="laser_frame">
    <sensor name="laser" type="ray">
      <pose>0 0 0 0 0 0</pose>
      <visualize>true</visualize>
      <update_rate>10</update_rate>
      <ray>
        <scan>
          <horizontal>
            <samples>360</samples>
            <min_angle>-3.14159</min_angle>
            <max_angle>3.14159</max_angle>
          </horizontal>
        </scan>
        <range>
          <min>0.3</min>
          <max>12</max>
        </range>
        <!-- 🔥 AJOUT BRUIT RÉALISTE -->
        <noise>
          <type>gaussian</type>
          <mean>0.0</mean>
          <stddev>0.01</stddev>
        </noise>
      </ray>
      <plugin name="laser_controller" filename="libgazebo_ros_ray_sensor.so">
        <ros>
          <argument>~/out:=scan</argument>
        </ros>
        <output_type>sensor_msgs/LaserScan</output_type>
        <frame_name>laser_frame</frame_name>
      </plugin>
    </sensor>
  </gazebo>

  <!-- ================================================================ -->
  <!-- PLUGIN ROS2_CONTROL GAZEBO -->
  <!-- ================================================================ -->
  
  <gazebo>
    <plugin name="gazebo_ros2_control" filename="libgazebo_ros2_control.so">
      <parameters>$(find my_robot_controller)/config/my_controllers.yaml</parameters>
      <!-- 🔥 AJOUT PARAMÈTRES SIMULATION -->
      <ros>
        <namespace></namespace>
      </ros>
    </plugin>
  </gazebo>

</robot>